Workbook

Sheet Instructions
D4: Instructions
B6: Le Big-Five Personality Trait Short Questionnaire (BFPTSQ; Morizot, 2014) est un
B7: inventaire de personnalité court en 50 items et faisant usage d'une
B8: échelle de Likert à 5 ancrages.
B10: Fortement en désaccord
B11: Un peu en désaccord
B12: Opinion neutre
B13: Un peu d'accord
B14: Fortement d'accord
D16: Étapes
B18: 1. | C18: Pour répondre au questionnaire, vous devez ouvrir la feuille de calcul
C19: "Questionnaire de personnalité" de ce document. Vous y trouverez
C20: un tableau semblable à celui ci-dessous, mais plus complet.
B23: 2. | C23: Afin de répondre aux questions, vous devez d'abord cliquer sur la
C24: cellule "Choix de réponse" faisant face à chaque question.
B31: 3. | C31: Vous verrez alors un petit bouton gris présentant deux flèches, tel que
C32: montré par le cercle rouge ci-dessous. Si vous cliquez sur ce bouton
C33: vous verrez apparaître un menu déroulant qui vous permettra
C34: d'effectuer votre choix de réponse
B42: 4. | C42: Après avoir sélectionné correctement toutes vos réponses, vous devrez
C43: ouvrir la feuille de calcul "Profil graphique". Sur cette feuille, vous devriez
C44: être en mesure de voir votre score global pour chacun des traits du Big Five
C45: dans le tableau «Profil de personnalité», tel qu'illustré par l'exemple
C46: ci-dessous.
C56: Vous devriez aussi être en mesure de voir une représentation graphique de
C57: votre profil de personnalité, tel qu'illustré par l'exemple ci-dessous.
C76: Voilà! Bon cours à tous.
C80: Morizot, J. (2014). Construct Validity of Adolescents’ Self-Reported Big Five Personality Traits Importance of Conceptual Breadth and Initial Validation of a Short Measure. Assessment, 21(5), 580-606.

Sheet Questionnaire de personnalité
D2: Voici une liste de caractéristiques que les personnes peuvent manifester dans leur vie de tous les jours. Nous voudrions que vous indiquiez à quel
D3: point chacune de ces caractéristiques s’applique à vous. Ne pensez pas à des situations ou des personnes particulières, mais indiquez simplement
D4: à quel point ces caractéristiques s’appliquent à vous habituellement. Tout le monde peut être différents(es) pour toutes ces caractéristiques, il n’y
D5: a donc pas de bonnes ou de mauvaises réponses. S’il vous plaît sélectionnez un des choix de réponse afin d’indiquer à quel point vous êtes en accord ou
D6: en désaccord avec chacun des énoncés. Si vous n’êtes pas certain(e) d’une réponse et que vous hésitez, choisissez quand-même celle qui
D7: vous représente le mieux.
D9: Big-Five Personality Trait Short Questionnaire (BFPTSQ) - version française
D10: Items | E10: Choix de réponse
D11: Je me perçois comme quelqu’un qui …
D12: 1. est original(e), a souvent de nouvelles idées. | E12: Fortement en désaccord | F12: =IF(E12="Fortement en désaccord",0)+IF(E12="Un peu en désaccord",1)+IF(E12="Opinion neutre",2)+IF(E12="Un peu d'accord",3)+IF(E12="Fortement d'accord",4) -> 0
D13: 2. aime parler, exprime son opinion. | F13: =IF(E13="Fortement en désaccord",0)+IF(E13="Un peu en désaccord",1)+IF(E13="Opinion neutre",2)+IF(E13="Un peu d'accord",3)+IF(E13="Fortement d'accord",4) -> 0
D14: 3. a tendance à critiquer les autres. | F14: =IF(E14="Fortement en désaccord",4)+IF(E14="Un peu en désaccord",3)+IF(E14="Opinion neutre",2)+IF(E14="Un peu d'accord",1)+IF(E14="Fortement d'accord",0) -> 0 | G14: R
D15: 4. travaille consciencieusement, fait bien les choses qu’il/elle a à faire. | F15: =IF(E15="Fortement en désaccord",0)+IF(E15="Un peu en désaccord",1)+IF(E15="Opinion neutre",2)+IF(E15="Un peu d'accord",3)+IF(E15="Fortement d'accord",4) -> 0
D16: 5. a tendance à être facilement déprimé(e), triste. | F16: =IF(E16="Fortement en désaccord",4)+IF(E16="Un peu en désaccord",3)+IF(E16="Opinion neutre",2)+IF(E16="Un peu d'accord",1)+IF(E16="Fortement d'accord",0) -> 0 | G16: R
D17: 6. est curieux(se) à propos de plusieurs choses différentes. | F17: =IF(E17="Fortement en désaccord",0)+IF(E17="Un peu en désaccord",1)+IF(E17="Opinion neutre",2)+IF(E17="Un peu d'accord",3)+IF(E17="Fortement d'accord",4) -> 0
D18: 7. est réservé(e) ou timide, a de la difficulté à aller vers les autres. | F18: =IF(E18="Fortement en désaccord",4)+IF(E18="Un peu en désaccord",3)+IF(E18="Opinion neutre",2)+IF(E18="Un peu d'accord",1)+IF(E18="Fortement d'accord",0) -> 0 | G18: R
D19: 8. est serviable et généreux(se) avec les autres. | F19: =IF(E19="Fortement en désaccord",0)+IF(E19="Un peu en désaccord",1)+IF(E19="Opinion neutre",2)+IF(E19="Un peu d'accord",3)+IF(E19="Fortement d'accord",4) -> 0
D20: 9. peut être un peu négligent(e) et insouciant(e). | F20: =IF(E20="Fortement en désaccord",4)+IF(E20="Un peu en désaccord",3)+IF(E20="Opinion neutre",2)+IF(E20="Un peu d'accord",1)+IF(E20="Fortement d'accord",0) -> 0 | G20: R
D21: 10. est généralement relaxe, gère bien le stress. | F21: =IF(E21="Fortement en désaccord",0)+IF(E21="Un peu en désaccord",1)+IF(E21="Opinion neutre",2)+IF(E21="Un peu d'accord",3)+IF(E21="Fortement d'accord",4) -> 0
D22: 11. est ingénieux(se), qui réfléchit beaucoup. | F22: =IF(E22="Fortement en désaccord",0)+IF(E22="Un peu en désaccord",1)+IF(E22="Opinion neutre",2)+IF(E22="Un peu d'accord",3)+IF(E22="Fortement d'accord",4) -> 0
D23: 12. est plein(e) d’énergie, aime être toujours actif(ive). | F23: =IF(E23="Fortement en désaccord",0)+IF(E23="Un peu en désaccord",1)+IF(E23="Opinion neutre",2)+IF(E23="Un peu d'accord",3)+IF(E23="Fortement d'accord",4) -> 0
D24: 13. provoque des chicanes ou des disputes avec les autres. | F24: =IF(E24="Fortement en désaccord",4)+IF(E24="Un peu en désaccord",3)+IF(E24="Opinion neutre",2)+IF(E24="Un peu d'accord",1)+IF(E24="Fortement d'accord",0) -> 0 | G24: R
D25: 14. est un(une) étudiant(e) / travailleur(euse) fiable, sur qui on peut compter. | F25: =IF(E25="Fortement en désaccord",0)+IF(E25="Un peu en désaccord",1)+IF(E25="Opinion neutre",2)+IF(E25="Un peu d'accord",3)+IF(E25="Fortement d'accord",4) -> 0
D26: 15. peut être tendu(e), stressé(e). | F26: =IF(E26="Fortement en désaccord",4)+IF(E26="Un peu en désaccord",3)+IF(E26="Opinion neutre",2)+IF(E26="Un peu d'accord",1)+IF(E26="Fortement d'accord",0) -> 0 | G26: R
D27: 16. a beaucoup d’imagination. | F27: =IF(E27="Fortement en désaccord",0)+IF(E27="Un peu en désaccord",1)+IF(E27="Opinion neutre",2)+IF(E27="Un peu d'accord",3)+IF(E27="Fortement d'accord",4) -> 0
D28: 17. est un(une) leader, capable de convaincre les autres. | F28: =IF(E28="Fortement en désaccord",0)+IF(E28="Un peu en désaccord",1)+IF(E28="Opinion neutre",2)+IF(E28="Un peu d'accord",3)+IF(E28="Fortement d'accord",4) -> 0
D29: 18. est indulgent(e), pardonne facilement. | F29: =IF(E29="Fortement en désaccord",0)+IF(E29="Un peu en désaccord",1)+IF(E29="Opinion neutre",2)+IF(E29="Un peu d'accord",3)+IF(E29="Fortement d'accord",4) -> 0
D30: 19. a tendance à être désorganisé(e), en désordre. | F30: =IF(E30="Fortement en désaccord",4)+IF(E30="Un peu en désaccord",3)+IF(E30="Opinion neutre",2)+IF(E30="Un peu d'accord",1)+IF(E30="Fortement d'accord",0) -> 0 | G30: R
D31: 20. s’inquiète beaucoup à propos de plusieurs choses. | F31: =IF(E31="Fortement en désaccord",4)+IF(E31="Un peu en désaccord",3)+IF(E31="Opinion neutre",2)+IF(E31="Un peu d'accord",1)+IF(E31="Fortement d'accord",0) -> 0 | G31: R
D32: 21. est inventif(ive), créatif(ive). | F32: =IF(E32="Fortement en désaccord",0)+IF(E32="Un peu en désaccord",1)+IF(E32="Opinion neutre",2)+IF(E32="Un peu d'accord",3)+IF(E32="Fortement d'accord",4) -> 0
D33: 22. est plutôt tranquille, ne parle pas beaucoup. | F33: =IF(E33="Fortement en désaccord",4)+IF(E33="Un peu en désaccord",3)+IF(E33="Opinion neutre",2)+IF(E33="Un peu d'accord",1)+IF(E33="Fortement d'accord",0) -> 0 | G33: R
D34: 23. fait généralement confiance aux autres. | F34: =IF(E34="Fortement en désaccord",0)+IF(E34="Un peu en désaccord",1)+IF(E34="Opinion neutre",2)+IF(E34="Un peu d'accord",3)+IF(E34="Fortement d'accord",4) -> 0
D35: 24. a tendance à être paresseux(se). | F35: =IF(E35="Fortement en désaccord",4)+IF(E35="Un peu en désaccord",3)+IF(E35="Opinion neutre",2)+IF(E35="Un peu d'accord",1)+IF(E35="Fortement d'accord",0) -> 0 | G35: R
D36: 25. est stable émotivement, n’est pas facilement bouleversé(e). | F36: =IF(E36="Fortement en désaccord",0)+IF(E36="Un peu en désaccord",1)+IF(E36="Opinion neutre",2)+IF(E36="Un peu d'accord",3)+IF(E36="Fortement d'accord",4) -> 0
D37: 26. aime les expériences artistiques ou esthétiques. | F37: =IF(E37="Fortement en désaccord",0)+IF(E37="Un peu en désaccord",1)+IF(E37="Opinion neutre",2)+IF(E37="Un peu d'accord",3)+IF(E37="Fortement d'accord",4) -> 0
D38: 27. montre de l’assurance, est capable de s’affirmer. | F38: =IF(E38="Fortement en désaccord",0)+IF(E38="Un peu en désaccord",1)+IF(E38="Opinion neutre",2)+IF(E38="Un peu d'accord",3)+IF(E38="Fortement d'accord",4) -> 0
D39: 28. peut être distant(e) et froid(e) avec les autres. | F39: =IF(E39="Fortement en désaccord",4)+IF(E39="Un peu en désaccord",3)+IF(E39="Opinion neutre",2)+IF(E39="Un peu d'accord",1)+IF(E39="Fortement d'accord",0) -> 0 | G39: R
D40: 29. persévère jusqu’à ce que la tâche à accomplir soit terminée. | F40: =IF(E40="Fortement en désaccord",0)+IF(E40="Un peu en désaccord",1)+IF(E40="Opinion neutre",2)+IF(E40="Un peu d'accord",3)+IF(E40="Fortement d'accord",4) -> 0
D41: 30. peut être d’humeur changeante. | F41: =IF(E41="Fortement en désaccord",4)+IF(E41="Un peu en désaccord",3)+IF(E41="Opinion neutre",2)+IF(E41="Un peu d'accord",1)+IF(E41="Fortement d'accord",0) -> 0 | G41: R
D42: 31. n’est pas vraiment intéressé(e) par les différentes cultures, leurs coutumes et valeurs. | F42: =IF(E42="Fortement en désaccord",4)+IF(E42="Un peu en désaccord",3)+IF(E42="Opinion neutre",2)+IF(E42="Un peu d'accord",1)+IF(E42="Fortement d'accord",0) -> 0 | G42: R
...

Sheet Profil graphique
C2: Profil de personnalité
B3: Ouverture | C3: ='Questionnaire de personnalité'!F12+'Questionnaire de personnalité'!F17+'Questionnaire de personnalité'!F22+'Questionnaire de personnalité'!F27+'Questionnaire de personnalité'!F32+'Questionnaire de personnalité'!F37+'Questionnaire de personnalité'!F42+'Questionnaire de personnalité'!F47+'Questionnaire de personnalité'!F52+'Questionnaire de personnalité'!F57 -> 0
B4: Extraversion | C4: =SUM('Questionnaire de personnalité'!F13+'Questionnaire de personnalité'!F18+'Questionnaire de personnalité'!F23+'Questionnaire de personnalité'!F28+'Questionnaire de personnalité'!F33+'Questionnaire de personnalité'!F38+'Questionnaire de personnalité'!F43+'Questionnaire de personnalité'!F48+'Questionnaire de personnalité'!F53+'Questionnaire de personnalité'!F58) -> 0
B5: Amabilité | C5: =SUM('Questionnaire de personnalité'!F14+'Questionnaire de personnalité'!F19+'Questionnaire de personnalité'!F24+'Questionnaire de personnalité'!F29+'Questionnaire de personnalité'!F34+'Questionnaire de personnalité'!F39+'Questionnaire de personnalité'!F44+'Questionnaire de personnalité'!F49+'Questionnaire de personnalité'!F54+'Questionnaire de personnalité'!F59) -> 0
B6: Contrôle | C6: =SUM('Questionnaire de personnalité'!F15+'Questionnaire de personnalité'!F20+'Questionnaire de personnalité'!F25+'Questionnaire de personnalité'!F30+'Questionnaire de personnalité'!F35+'Questionnaire de personnalité'!F40+'Questionnaire de personnalité'!F45+'Questionnaire de personnalité'!F50+'Questionnaire de personnalité'!F55+'Questionnaire de personnalité'!F60) -> 0
B7: Stabilité émotive | C7: =SUM('Questionnaire de personnalité'!F16+'Questionnaire de personnalité'!F21+'Questionnaire de personnalité'!F26+'Questionnaire de personnalité'!F31+'Questionnaire de personnalité'!F36+'Questionnaire de personnalité'!F41+'Questionnaire de personnalité'!F46+'Questionnaire de personnalité'!F51+'Questionnaire de personnalité'!F56+'Questionnaire de personnalité'!F61) -> 0

Sheet Comparatif 18-29 ans
C2: Profil de personnalité
B3: Ouverture | C3: ='Questionnaire de personnalité'!F12+'Questionnaire de personnalité'!F17+'Questionnaire de personnalité'!F22+'Questionnaire de personnalité'!F27+'Questionnaire de personnalité'!F32+'Questionnaire de personnalité'!F37+'Questionnaire de personnalité'!F42+'Questionnaire de personnalité'!F47+'Questionnaire de personnalité'!F52+'Questionnaire de personnalité'!F57 -> 0 | D3: =((C3-28.45)/5.736) -> -4.9599024 | E3: =((C3-28.29)/5.753) -> -4.9174344
B4: Extraversion | C4: =SUM('Questionnaire de personnalité'!F13+'Questionnaire de personnalité'!F18+'Questionnaire de personnalité'!F23+'Questionnaire de personnalité'!F28+'Questionnaire de personnalité'!F33+'Questionnaire de personnalité'!F38+'Questionnaire de personnalité'!F43+'Questionnaire de personnalité'!F48+'Questionnaire de personnalité'!F53+'Questionnaire de personnalité'!F58) -> 0 | D4: =((C4-28.19)/6.654) -> -4.2365494 | E4: =((C4-27.53)/6.671) -> -4.1268176
B5: Amabilité | C5: =SUM('Questionnaire de personnalité'!F14+'Questionnaire de personnalité'!F19+'Questionnaire de personnalité'!F24+'Questionnaire de personnalité'!F29+'Questionnaire de personnalité'!F34+'Questionnaire de personnalité'!F39+'Questionnaire de personnalité'!F44+'Questionnaire de personnalité'!F49+'Questionnaire de personnalité'!F54+'Questionnaire de personnalité'!F59) -> 0 | D5: =((C5-26.9)/5.657) -> -4.7551706 | E5: =((C5-29.39)/5.181) -> -5.6726501
B6: Contrôle | C6: =SUM('Questionnaire de personnalité'!F15+'Questionnaire de personnalité'!F20+'Questionnaire de personnalité'!F25+'Questionnaire de personnalité'!F30+'Questionnaire de personnalité'!F35+'Questionnaire de personnalité'!F40+'Questionnaire de personnalité'!F45+'Questionnaire de personnalité'!F50+'Questionnaire de personnalité'!F55+'Questionnaire de personnalité'!F60) -> 0 | D6: =((C6-25.48)/5.532) -> -4.6059291 | E6: =((C6-28.47)/6.155) -> -4.6255077
B7: Stabilité émotive | C7: =SUM('Questionnaire de personnalité'!F16+'Questionnaire de personnalité'!F21+'Questionnaire de personnalité'!F26+'Questionnaire de personnalité'!F31+'Questionnaire de personnalité'!F36+'Questionnaire de personnalité'!F41+'Questionnaire de personnalité'!F46+'Questionnaire de personnalité'!F51+'Questionnaire de personnalité'!F56+'Questionnaire de personnalité'!F61) -> 0 | D7: =((C7-24.16)/7.678) -> -3.1466528 | E7: =((C7-19.29)/7.671) -> -2.5146656

Sheet Comparatif 30-39 ans
C2: Profil de personnalité
B3: Ouverture | C3: ='Questionnaire de personnalité'!F12+'Questionnaire de personnalité'!F17+'Questionnaire de personnalité'!F22+'Questionnaire de personnalité'!F27+'Questionnaire de personnalité'!F32+'Questionnaire de personnalité'!F37+'Questionnaire de personnalité'!F42+'Questionnaire de personnalité'!F47+'Questionnaire de personnalité'!F52+'Questionnaire de personnalité'!F57 -> 0 | D3: =((C3-28.51)/6.566) -> -4.3420652 | E3: =((C3-28.58)/6.2) -> -4.6096774
B4: Extraversion | C4: =SUM('Questionnaire de personnalité'!F13+'Questionnaire de personnalité'!F18+'Questionnaire de personnalité'!F23+'Questionnaire de personnalité'!F28+'Questionnaire de personnalité'!F33+'Questionnaire de personnalité'!F38+'Questionnaire de personnalité'!F43+'Questionnaire de personnalité'!F48+'Questionnaire de personnalité'!F53+'Questionnaire de personnalité'!F58) -> 0 | D4: =((C4-27.61)/6.892) -> -4.006094 | E4: =((C4-28.48)/6.591) -> -4.3210438
B5: Amabilité | C5: =SUM('Questionnaire de personnalité'!F14+'Questionnaire de personnalité'!F19+'Questionnaire de personnalité'!F24+'Questionnaire de personnalité'!F29+'Questionnaire de personnalité'!F34+'Questionnaire de personnalité'!F39+'Questionnaire de personnalité'!F44+'Questionnaire de personnalité'!F49+'Questionnaire de personnalité'!F54+'Questionnaire de personnalité'!F59) -> 0 | D5: =((C5-27.56)/6.053) -> -4.5531142 | E5: =((C5-29.51)/5.778) -> -5.1073036
B6: Contrôle | C6: =SUM('Questionnaire de personnalité'!F15+'Questionnaire de personnalité'!F20+'Questionnaire de personnalité'!F25+'Questionnaire de personnalité'!F30+'Questionnaire de personnalité'!F35+'Questionnaire de personnalité'!F40+'Questionnaire de personnalité'!F45+'Questionnaire de personnalité'!F50+'Questionnaire de personnalité'!F55+'Questionnaire de personnalité'!F60) -> 0 | D6: =((C6-28.16)/5.875) -> -4.7931915 | E6: =((C6-30.51)/5.455) -> -5.5930339
B7: Stabilité émotive | C7: =SUM('Questionnaire de personnalité'!F16+'Questionnaire de personnalité'!F21+'Questionnaire de personnalité'!F26+'Questionnaire de personnalité'!F31+'Questionnaire de personnalité'!F36+'Questionnaire de personnalité'!F41+'Questionnaire de personnalité'!F46+'Questionnaire de personnalité'!F51+'Questionnaire de personnalité'!F56+'Questionnaire de personnalité'!F61) -> 0 | D7: =((C7-23.87)/7.319) -> -3.2613745 | E7: =((C7-21.19)/8.005) -> -2.6470956

Sheet Comparatif 40-49 ans
C2: Profil de personnalité
B3: Ouverture | C3: ='Questionnaire de personnalité'!F12+'Questionnaire de personnalité'!F17+'Questionnaire de personnalité'!F22+'Questionnaire de personnalité'!F27+'Questionnaire de personnalité'!F32+'Questionnaire de personnalité'!F37+'Questionnaire de personnalité'!F42+'Questionnaire de personnalité'!F47+'Questionnaire de personnalité'!F52+'Questionnaire de personnalité'!F57 -> 0 | D3: =((C3-27.8)/5.628) -> -4.9395878 | E3: =((C3-27.36)/7.148) -> -3.8276441
B4: Extraversion | C4: =SUM('Questionnaire de personnalité'!F13+'Questionnaire de personnalité'!F18+'Questionnaire de personnalité'!F23+'Questionnaire de personnalité'!F28+'Questionnaire de personnalité'!F33+'Questionnaire de personnalité'!F38+'Questionnaire de personnalité'!F43+'Questionnaire de personnalité'!F48+'Questionnaire de personnalité'!F53+'Questionnaire de personnalité'!F58) -> 0 | D4: =((C4-27.4)/6.754) -> -4.0568552 | E4: =((C4-27.05)/7.352) -> -3.6792709
B5: Amabilité | C5: =SUM('Questionnaire de personnalité'!F14+'Questionnaire de personnalité'!F19+'Questionnaire de personnalité'!F24+'Questionnaire de personnalité'!F29+'Questionnaire de personnalité'!F34+'Questionnaire de personnalité'!F39+'Questionnaire de personnalité'!F44+'Questionnaire de personnalité'!F49+'Questionnaire de personnalité'!F54+'Questionnaire de personnalité'!F59) -> 0 | D5: =((C5-28.75)/5.184) -> -5.5459105 | E5: =((C5-31.9)/4.506) -> -7.0794496
B6: Contrôle | C6: =SUM('Questionnaire de personnalité'!F15+'Questionnaire de personnalité'!F20+'Questionnaire de personnalité'!F25+'Questionnaire de personnalité'!F30+'Questionnaire de personnalité'!F35+'Questionnaire de personnalité'!F40+'Questionnaire de personnalité'!F45+'Questionnaire de personnalité'!F50+'Questionnaire de personnalité'!F55+'Questionnaire de personnalité'!F60) -> 0 | D6: =((C6-30.18)/5.542) -> -5.4456875 | E6: =((C6-32.96)/5.239) -> -6.291277
B7: Stabilité émotive | C7: =SUM('Questionnaire de personnalité'!F16+'Questionnaire de personnalité'!F21+'Questionnaire de personnalité'!F26+'Questionnaire de personnalité'!F31+'Questionnaire de personnalité'!F36+'Questionnaire de personnalité'!F41+'Questionnaire de personnalité'!F46+'Questionnaire de personnalité'!F51+'Questionnaire de personnalité'!F56+'Questionnaire de personnalité'!F61) -> 0 | D7: =((C7-25.45)/6.811) -> -3.7366026 | E7: =((C7-22.6)/8.153) -> -2.7719858
