Workbook

Sheet Plans préliminaires
A1: PLANS PRÉLIMINAIRES
A2: Nom du produit | C2: Stock au départ | D2: Taille de lot | E2: UÉ | F2: Délai
A3: Produit A | C3: 100 | D3: X 150 | E3: 2 | F3: 1
A5: Semaine | C5: 1 | D5: 2 | E5: 3 | F5: 4 | G5: 5 | H5: 6 | I5: 7 | J5: 8
A6: Prévisions | C6: 75 | D6: 65 | E6: 65 | F6: 75 | G6: 75 | H6: 75 | I6: 60 | J6: 30
A7: Commandes acceptées | C7: 35 | D7: 90 | E7: 60 | F7: 80 | G7: 60 | H7: 60 | I7: 30 | J7: 15
A8: Stock projeté | B8: =C3 -> 100
A9: Stock disponible à la vente | B9: =C3 -> 100
A10: Réception planifiée
A11: Lancement planifié
A13: Nom du produit | C13: Stock au départ | D13: Taille de lot | E13: UÉ | F13: Délai
A14: Produit B | C14: 300 | D14: X 75 | E14: 3 | F14: 1
A16: Semaine | C16: 1 | D16: 2 | E16: 3 | F16: 4 | G16: 5 | H16: 6 | I16: 7 | J16: 8
A17: Prévisions | C17: 60 | D17: 120 | E17: 80 | F17: 40 | G17: 30 | H17: 75 | I17: 20 | J17: 20
A18: Commandes acceptées | C18: 35 | D18: 150 | E18: 60 | F18: 30 | G18: 55 | H18: 35 | I18: 10 | J18: 5
A19: Stock projeté | B19: =C14 -> 300
A20: Stock disponible à la vente | B20: =C14 -> 300
A21: Réception planifiée
A22: Lancement planifié
A24: Nom du produit | C24: Stock au départ | D24: Taille de lot | E24: UÉ | F24: Délai
A27: Semaine | C27: 1 | D27: 2 | E27: 3 | F27: 4 | G27: 5 | H27: 6 | I27: 7 | J27: 8
A28: Prévisions
A29: Commandes acceptées
A30: Stock projeté | B30: =C25 -> 0
A31: Stock disponible à la vente | B31: =C25 -> 0
A32: Réception planifiée
A33: Lancement planifié
A35: PLANIFICATION SOMMAIRE DES CAPACITÉS (UNITÉS ÉQUIVALENTES)
A36: Présentez ici la planification sommaire correspondant à vos plans préliminaires
A37: Semaine | C37: 1 | D37: 2 | E37: 3 | F37: 4 | G37: 5 | H37: 6 | I37: 7 | J37: 8
B38: =A3 -> Produit A
B39: =A14 -> Produit B
A41: Capacité totale requise
A42: Capacité totale disponible
A45: PLANIFICATION SOMMAIRE DES CAPACITÉS (UNITÉS ÉQUIVALENTES)
A46: Utilisez cette espace pour déterminer les changements à apporter
A47: Semaine | C47: 1 | D47: 2 | E47: 3 | F47: 4 | G47: 5 | H47: 6 | I47: 7 | J47: 8
B48: =B38 -> Produit A
B49: =B39 -> Produit B
A51: Capacité totale requise
...

Sheet Plans finaux
A1: PLANS FINAUX
A2: Nom du produit | C2: Stock au départ | D2: Taille de lot | E2: UÉ | F2: Délai
A3: ='Plans préliminaires'!A3 -> Produit A | C3: ='Plans préliminaires'!C3 -> 100 | D3: ='Plans préliminaires'!D3 -> X 150 | E3: ='Plans préliminaires'!E3 -> 2 | F3: ='Plans préliminaires'!F3 -> 1
A5: Semaine | C5: 1 | D5: 2 | E5: 3 | F5: 4 | G5: 5 | H5: 6 | I5: 7 | J5: 8
A6: Prévisions | C6: ='Plans préliminaires'!C6 -> 75 | D6: ='Plans préliminaires'!D6 -> 65 | E6: ='Plans préliminaires'!E6 -> 65 | F6: ='Plans préliminaires'!F6 -> 75 | G6: ='Plans préliminaires'!G6 -> 75 | H6: ='Plans préliminaires'!H6 -> 75 | I6: ='Plans préliminaires'!I6 -> 60 | J6: ='Plans préliminaires'!J6 -> 30
A7: Commandes acceptées | C7: ='Plans préliminaires'!C7 -> 35 | D7: ='Plans préliminaires'!D7 -> 90 | E7: ='Plans préliminaires'!E7 -> 60 | F7: ='Plans préliminaires'!F7 -> 80 | G7: ='Plans préliminaires'!G7 -> 60 | H7: ='Plans préliminaires'!H7 -> 60 | I7: ='Plans préliminaires'!I7 -> 30 | J7: ='Plans préliminaires'!J7 -> 15
A8: Stock projeté | B8: =C3 -> 100
A9: Stock disponible à la vente | B9: =C3 -> 100
A10: Réception planifiée
A11: Lancement planifié
A13: Nom du produit | C13: Stock au départ | D13: Taille de lot | E13: UÉ | F13: Délai
A14: ='Plans préliminaires'!A14 -> Produit B | C14: ='Plans préliminaires'!C14 -> 300 | D14: ='Plans préliminaires'!D14 -> X 75 | E14: ='Plans préliminaires'!E14 -> 3 | F14: ='Plans préliminaires'!F14 -> 1
A16: Semaine | C16: 1 | D16: 2 | E16: 3 | F16: 4 | G16: 5 | H16: 6 | I16: 7 | J16: 8
A17: Prévisions | C17: ='Plans préliminaires'!C17 -> 60 | D17: ='Plans préliminaires'!D17 -> 120 | E17: ='Plans préliminaires'!E17 -> 80 | F17: ='Plans préliminaires'!F17 -> 40 | G17: ='Plans préliminaires'!G17 -> 30 | H17: ='Plans préliminaires'!H17 -> 75 | I17: ='Plans préliminaires'!I17 -> 20 | J17: ='Plans préliminaires'!J17 -> 20
A18: Commandes acceptées | C18: ='Plans préliminaires'!C18 -> 35 | D18: ='Plans préliminaires'!D18 -> 150 | E18: ='Plans préliminaires'!E18 -> 60 | F18: ='Plans préliminaires'!F18 -> 30 | G18: ='Plans préliminaires'!G18 -> 55 | H18: ='Plans préliminaires'!H18 -> 35 | I18: ='Plans préliminaires'!I18 -> 10 | J18: ='Plans préliminaires'!J18 -> 5
A19: Stock projeté | B19: =C14 -> 300
A20: Stock disponible à la vente | B20: =C14 -> 300
A21: Réception planifiée
A22: Lancement planifié
A24: Nom du produit | C24: Stock au départ | D24: Taille de lot | E24: UÉ | F24: Délai
A25: ='Plans préliminaires'!A25 -> 0 | C25: ='Plans préliminaires'!C25 -> 0 | D25: ='Plans préliminaires'!D25 -> 0 | E25: ='Plans préliminaires'!E25 -> 0 | F25: ='Plans préliminaires'!F25 -> 0
A27: Semaine | C27: 1 | D27: 2 | E27: 3 | F27: 4 | G27: 5 | H27: 6 | I27: 7 | J27: 8
A28: Prévisions | C28: ='Plans préliminaires'!C28 -> 0 | D28: ='Plans préliminaires'!D28 -> 0 | E28: ='Plans préliminaires'!E28 -> 0 | F28: ='Plans préliminaires'!F28 -> 0 | G28: ='Plans préliminaires'!G28 -> 0 | H28: ='Plans préliminaires'!H28 -> 0 | I28: ='Plans préliminaires'!I28 -> 0 | J28: ='Plans préliminaires'!J28 -> 0
A29: Commandes acceptées | C29: ='Plans préliminaires'!C29 -> 0 | D29: ='Plans préliminaires'!D29 -> 0 | E29: ='Plans préliminaires'!E29 -> 0 | F29: ='Plans préliminaires'!F29 -> 0 | G29: ='Plans préliminaires'!G29 -> 0 | H29: ='Plans préliminaires'!H29 -> 0 | I29: ='Plans préliminaires'!I29 -> 0 | J29: ='Plans préliminaires'!J29 -> 0
A30: Stock projeté | B30: =C25 -> 0
A31: Stock disponible à la vente | B31: =C25 -> 0
A32: Réception planifiée
A33: Lancement planifié
A35: PLANIFICATION SOMMAIRE DES CAPACITÉS (UNITÉS ÉQUIVALENTES)
A37: Semaine | C37: 1 | D37: 2 | E37: 3 | F37: 4 | G37: 5 | H37: 6 | I37: 7 | J37: 8
B38: =A3 -> Produit A
B39: =A14 -> Produit B
A41: Capacité totale requise
A42: Capacité totale disponible
