Workbook

Sheet Activité 
A1: Atelier | G1: Exercice utilisé pour le cours:
A2: Travail à faire - Étudiants | G2: Comptabilité de gestion
A3: Imputation- Centres de coûts
E5: Centres de coûts | N5: Processus de fabrication
E6: Atelier mécanisé | G6: Atelier de finition | I6: TOTAL | M6: Centre de coût 1: | O6: ATELIER MÉCANISÉ
C7: FGF Variables | M7: Remplissage | Q7: Emballage
C8: Maintenance (pièces, huile) | E8: 40000 | G8: 0 | I8: =E8+G8 -> 40000 | M8: Robe noire | Q8: Robe noire
C9: Électricité | E9: 15000 | G9: 5000 | I9: =E9+G9 -> 20000 | M9: Fall Flower
C10: Outillage pour la finition | E10: 0 | G10: 105000 | I10: =E10+G10 -> 105000
C11: (colle, outillages,rubans, etc.) | E11: =SUM(E8:E10) -> 55000 | G11: =SUM(G8:G10) -> 110000 | I11: =E11+G11 -> 165000 | M11: Centre de coût 2: | O11: ATELIER DE FINITION
C12: FGF fixes | M12: Remplissage | Q12: Finition
C13: Loyer | E13: 232000 | G13: 144000 | I13: =E13+G13 -> 376000 | Q13: Fall Flower
C14: Amortissement- machine de remplissage | E14: 1500100 | G14: 0 | I14: =E14+G14 -> 1500100 | M14: Abeille | Q14: Abeille
C15: MOI - Salaire maintenance | E15: 265000 | G15: 0 | I15: =E15+G15 -> 265000
C16: MOI - Salaire superviseur | E16: 100000 | G16: 140000 | I16: =E16+G16 -> 240000
C17: Assurances et taxes | E17: 48000 | G17: 6000 | I17: =E17+G17 -> 54000
C18: Total FGF fixes | E18: =SUM(E13:E17) -> 2145100 | G18: =SUM(G13:G17) -> 290000 | I18: =E18+G18 -> 2435100
C20: Total FGF | E20: =E11+E18 -> 2200100 | G20: =G11+G18 -> 400000 | I20: =I11+I18 -> 2600100
C21: Base d'imputation | E21: Heures machine | G21: Heures de MOD
A23: Plusieurs centres coûts
A24: Travail à faire : Calculez le taux d'imputation par centre de coûts et imputez les FGF à chaque produit. Ne pas arrondir ! Faire les calculs directement dans le chiffrier Excel.
C26: Voici des données supplémentaires concernant la production du dernier exercice:
C27: Produits | E27: Robe noire | G27: Fall Flower | I27: Abeille
C28: Nombre d'unité à produire | E28: =Divers!H2 -> 400000 | G28: =Divers!I2 -> 15000 | I28: =Divers!J2 -> 50
C29: Heures-machine - Atelier mécanisé | E29: ='Révision 1 taux'!E34 -> 0.003 | G29: ='Révision 1 taux'!G34 -> 0.001 | I29: =Divers!J23 -> 0
C30: Heures MOD -Atelier mécanisé | E30: =Divers!H4 -> 0.01 | G30: 0.01 | I30: -
C31: Heures MOD -Atelier finition | E31: - | G31: 0.25 | I31: 2.5
C34: Total | E34: =E27 -> Robe noire | G34: =G27 -> Fall Flower | I34: =I27 -> Abeille | K34: TOTAL | M34: Indice: pensez au processus de fabrication.
C35: Heures-machine - Atelier Mécanisé | K35: =SUM(E35:I35) -> 0
C36: Heures de MOD- Atelier finition | K36: =SUM(E36:I36) -> 0 | M36: Est-ce que le produit passe par ce centre de coûts?
C38: Centre de coûts | E38: =E6 -> Atelier mécanisé | G38: =G6 -> Atelier de finition
C40: Total FGF par centre de coûts | E40: =E20 -> 2200100 | G40: =G20 -> 400000
C41: Base d'imputation | E41: =E21 -> Heures machine | G41: =G21 -> Heures de MOD
C42: Total de la base d'imputation
C44: Taux d'imputation
E46: =Divers!E10 | G46: =Divers!E11
C48: Frais généraux de fabrication- Centre | E48: =E34 -> Robe noire | G48: =G34 -> Fall Flower | I48: =I34 -> Abeille
C49: =E38 -> Atelier mécanisé
C50: =G38 -> Atelier de finition
C51: TOTAL des FGF unitaires
...

Sheet Révision 1 taux
B1: Atelier | H1: Exercice utilisé pour le cours:
B2: Travail à faire - Étudiants | H2: Comptabilité de gestion
B3: Imputation- Centres de coûts
A6: Un seul centre de coûts
A7: Objectif du calcul: Répartir le montant FGF total aux différents produits.
A8: Travail à faire: Calculez le taux d'imputation et imputer les FGF sachant que les frais généraux de fabrication totaux sont de : Faire les calculs dans le fichier Excel, ne pas arrondir. | K8: =Divers!K11 -> 2600100
A10: Scénario 1 : Calculer les coûts de fabrication unitaire en utilisant le nombre d'unités fabriqués comme base d'imputation
A12: Base d'imputation : nombre d'unités fabriquées | E12: =E55 -> Robe noire | G12: =G55 -> Fall Flower | I12: =I55 -> Abeille
C13: Nombre d'unités fabriqués | E13: =Divers!H2 -> 400000 | G13: =Divers!I2 -> 15000 | I13: =Divers!J2 -> 50
A15: Calcul du taux d'imputation | C15: FGF totaux | F15: = | I15: Taux d'imputation par unité
C16: Nombre d'unités fabriqués
C19: Produits | E19: =E12 -> Robe noire | G19: =G63 -> Fall Flower | I19: =I63 -> Abeille
C21: Matières premières | E21: =E65 -> 5 | G21: =G65 -> 20 | I21: =I65 -> 100
C22: Main d'œuvre directe | E22: =E66 -> 0.3 | G22: =G66 -> 15.3 | I22: =I66 -> 150
C23: Frais généraux de fabrication | G23: 6.26 | I23: 6.26 | K23: As-tu remarqué? On a alloué le même montant à chacun des produits.
C24: Coût de fabrication unitaire | E24: =SUM(E21:E23) -> 5.3 | I24: =SUM(I21:I23) -> 256.26
E26: =Divers!E20 | G26: =Divers!E21
A28: Scénario 2 : Calculer les coûts de fabrication unitaire en utilisant les heures-machines comme base d'imputation
A30: Base d'imputation : Heures machine
C31: Produits | E31: Robe noire | G31: Fall Flower | I31: Abeille | K31: TOTAL
C33: Nombre d'unité à produire | E33: 400000 | G33: 15000 | I33: 50 | K33: =E33+G33+I33 -> 415050
C34: Heures machine par unité | E34: 0.003 | G34: 0.001 | I34: 0 | K34: n/a
C35: Heures machine totale | M35: =Divers!E2 | N35: Surveillez les cases vertes pour des points de contrôle.
B37: Calcul du taux d'imputation | G37: Taux d'imputation par heure machine
C38: FGF totaux | F38: = | I38: =Divers!E3
C39: Heures-machine totales
C41: Produits | E41: =E31 -> Robe noire | G41: =G31 -> Fall Flower | I41: =I31 -> Abeille
C43: Matières premières | E43: 5 | G43: 20 | I43: 100
C44: Main d'œuvre directe | E44: =E56*30 -> 0.3 | G44: =0.01*30+0.25*60 -> 15.3 | I44: =I56*60 -> 150
C45: Frais généraux de fabrication | I45: 0 | K45: Utiliser le taux d'imputation pour calculer le coût unitaire des FGF
C46: Coût de fabrication unitaire | E46: =SUM(E43:E45) -> 5.3 | G46: =SUM(G43:G45) -> 35.3
E48: =Divers!E4 | G48: =Divers!E5 | I48: =Divers!E6
A53: Scénario 3 : Calculer les coûts de fabrication unitaire en utilisant les heures de MOD comme base d'imputation
A55: Base d'imputation : Heures de MOD | E55: =E31 -> Robe noire | G55: =G31 -> Fall Flower | I55: =I31 -> Abeille
C56: Heures de main d'œuvre directe par unité | E56: 0.01 | G56: 0.26 | I56: 2.5
C57: Heures de main d'œuvre directe totale | E57: =E56*E33 -> 4000 | G57: =G56*G33 -> 3900 | I57: =I56*I33 -> 125
A59: Calcul du taux d'imputation | C59: FGF totaux | F59: = | I59: Taux d'imputation par heure de mod
C60: Heures MOD totale
C63: Produits | E63: =E41 -> Robe noire | G63: =G41 -> Fall Flower | I63: =I41 -> Abeille
C65: Matières premières | E65: =E43 -> 5 | G65: =G43 -> 20 | I65: =I43 -> 100
...

Sheet Divers
A1: Réponse des étudiants | B1: Bonne réponse | C1: Marge de tolérance | D1: Binaire | E1: Message | H1: ='Révision 1 taux'!E31 -> Robe noire | I1: ='Révision 1 taux'!G31 -> Fall Flower | J1: ='Révision 1 taux'!I31 -> Abeille | K1: Total
A2: ='Révision 1 taux'!K35 -> 0 | B2: =K6 -> 1215 | C2: 0.01 | D2: =IF(ISNUMBER(A2),IF(ABS(A2-B2)<=C2,1,0),0) -> 0 | E2: =IF(D2=1,"Bon calcul, continue !","") | G2: Unités | H2: ='Révision 1 taux'!E33 -> 400000 | I2: ='Révision 1 taux'!G33 -> 15000 | J2: ='Révision 1 taux'!I33 -> 50 | K2: =SUM(H2:J2) -> 415050
A3: ='Révision 1 taux'!G38 -> 0 | B3: =K13 -> 2140 | C3: 0.01 | D3: =IF(ISNUMBER(A3),IF(ABS(A3-B3)<=C3,1,0),0) -> 0 | E3: =IF(D3=1,"Bravo!","") | G3: Heures machine | H3: ='Révision 1 taux'!E34 -> 0.003 | I3: ='Révision 1 taux'!G34 -> 0.001 | J3: ='Révision 1 taux'!I34 -> 0
A4: ='Révision 1 taux'!E45 -> 0 | B4: =H11 -> 6.42 | C4: 0.01 | D4: =IF(ISNUMBER(A4),IF(ABS(A4-B4)<=C4,1,0),0) -> 0 | E4: =IF(D4=1,"WOW !","") | G4: Heures de MOD | H4: ='Révision 1 taux'!E56 -> 0.01 | I4: ='Révision 1 taux'!G56 -> 0.26 | J4: ='Révision 1 taux'!I56 -> 2.5
A5: ='Révision 1 taux'!G45 -> 0 | B5: =I11 -> 2.14 | C5: 0.01 | D5: =IF(ISNUMBER(A5),IF(ABS(A5-B5)<=C5,1,0),0) -> 0 | E5: =IF(D5=1,"Incroyable !","")
A6: ='Révision 1 taux'!I46 -> 0 | B6: =J12 -> 250 | C6: 0.01 | D6: =IF(ISNUMBER(A6),IF(ABS(A6-B6)<=C6,1,0),0) -> 0 | E6: =IF(D6=1,"Super !","") | G6: Heures machine total | H6: =H2*H3 -> 1200 | I6: =I2*I3 -> 15 | J6: =J2*J3 -> 0 | K6: =SUM(H6:J6) -> 1215
A7: ='Révision 1 taux'!E67 -> 0 | B7: =H17 -> 3.24 | C7: 0.01 | D7: =IF(ISNUMBER(A7),IF(ABS(A7-B7)<=C7,1,0),0) -> 0 | E7: =IF(D7=1,"Génial!","") | G7: Heures MOD total | H7: =H4*H2 -> 4000 | I7: =I4*I2 -> 3900 | J7: =J4*J2 -> 125 | K7: =SUM(H7:J7) -> 8025
A8: ='Révision 1 taux'!G68 -> 0 | B8: =I18 -> 119.54 | C8: 0.01 | D8: =IF(ISNUMBER(A8),IF(ABS(A8-B8)<=C8,1,0),0) -> 0 | E8: =IF(D8=1,"Fabuleux!","") | G8: Coût fabrication (base heures-machine)
A9: ='Révision 1 taux'!I67 -> 0 | B9: =J17 -> 810 | C9: 0.01 | D9: =IF(ISNUMBER(A9),IF(ABS(A9-B9)<=C9,1,0),0) -> 0 | E9: =IF(D9=1,"C'est bon!","") | G9: MP | H9: ='Révision 1 taux'!E43 -> 5 | I9: ='Révision 1 taux'!G43 -> 20 | J9: ='Révision 1 taux'!I43 -> 100 | K9: =(H9*H$2)+(I9*I$2)+(J9*J$2) -> 2305000
A10: ='Activité '!E44 -> 0 | B10: =K32 -> 1810.7819 | C10: 0.01 | D10: =IF(ISNUMBER(A10),IF(ABS(A10-B10)<=C10,1,0),0) -> 0 | E10: =IF(D10=1,"Épatant","") | G10: MOD | H10: ='Révision 1 taux'!E44 -> 0.3 | I10: ='Révision 1 taux'!G44 -> 15.3 | J10: ='Révision 1 taux'!I44 -> 150 | K10: =(H10*H$2)+(I10*I$2)+(J10*J$2) -> 357000
A11: ='Activité '!G44 -> 0 | B11: =K33 -> 103.22581 | C11: 0.01 | D11: =IF(ISNUMBER(A11),IF(ABS(A11-B11)<=C11,1,0),0) -> 0 | E11: =IF(D11=1,"Bon travail!","") | G11: FGF (HM) | H11: =$K$13*H3 -> 6.42 | I11: =$K$13*I3 -> 2.14 | J11: =$K$13*J3 -> 0 | K11: 2600100
A12: ='Activité '!E51 -> 0 | B12: =H29 -> 5.4323457 | C12: 0.01 | D12: =IF(ISNUMBER(A12),IF(ABS(A12-B12)<=C12,1,0),0) -> 0 | E12: =IF(D12=1,"Excellent!","") | G12: Coût total | H12: =SUM(H9:H11) -> 11.72 | I12: =SUM(I9:I11) -> 37.44 | J12: =SUM(J9:J11) -> 250 | K12: =(H12*H$2)+(I12*I$2)+(J12*J$2) -> 5262100
A13: ='Activité '!G51 -> 0 | B13: =(I29+I30) -> 27.617234 | C13: 0.01 | D13: =IF(ISNUMBER(A13),IF(ABS(A13-B13)<=C13,1,0),0) -> 0 | E13: =IF(D13=1,"Juste Parfait!","") | G13: Taux imputation machine | K13: =K11/K6 -> 2140
A14: ='Activité '!I51 -> 0 | B14: =J30 -> 258.06452 | C14: 0.01 | D14: =IF(ISNUMBER(A14),IF(ABS(A14-B14)<=C14,1,0),0) -> 0 | E14: =IF(D14=1,"Bravo !","") | G14: Coût fabrication (base heures-MOD)
A15: ='Activité '!E59 -> 0 | B15: =H29 -> 5.4323457 | C15: 0.01 | D15: =IF(ISNUMBER(A15),IF(ABS(A15-B15)<=C15,1,0),0) -> 0 | E15: =IF(D15=1,"C'est bon !","") | G15: MP | H15: =H9 -> 5 | I15: =I9 -> 20 | J15: =J9 -> 100 | K15: =(H15*H$2)+(I15*I$2)+(J15*J$2) -> 2305000
A16: ='Activité '!G60 -> 0 | B16: =I31 -> 62.917234 | C16: 0.01 | D16: =IF(ISNUMBER(A16),IF(ABS(A16-B16)<=C16,1,0),0) -> 0 | E16: =IF(D16=1,"Bravo !","") | G16: MOD | H16: =H10 -> 0.3 | I16: =I10 -> 15.3 | J16: =J10 -> 150 | K16: =(H16*H$2)+(I16*I$2)+(J16*J$2) -> 357000
A17: ='Activité '!I60 -> 0 | B17: =J31 -> 508.06452 | C17: 0.01 | D17: =IF(ISNUMBER(A17),IF(ABS(A17-B17)<=C17,1,0),0) -> 0 | E17: =IF(D17=1,"Presque terminé !","") | G17: FGF(MOD) | H17: =$K$19*H4 -> 3.24 | I17: =$K$19*I4 -> 84.24 | J17: =$K$19*J4 -> 810 | K17: =K11 -> 2600100
A18: ='Révision 1 taux'!E23 -> 0 | B18: ='Révision 1 taux'!G15 -> 0 | C18: 0.01 | D18: =IF(ISNUMBER(A18),IF(ABS(A18-B18)<=C18,1,0),0) -> 1 | E18: =IF(D18=1,"Très bien","") -> Très bien | G18: Coût total | H18: =SUM(H15:H17) -> 8.54 | I18: =SUM(I15:I17) -> 119.54 | J18: =SUM(J15:J17) -> 1060
A19: ='Révision 1 taux'!G24 -> 0 | B19: ='Révision 1 taux'!G21+'Révision 1 taux'!G22+'Révision 1 taux'!G23 -> 41.56 | C19: 0.01 | D19: =IF(ISNUMBER(A19),IF(ABS(A19-B19)<=C19,1,0),0) -> 0 | E19: =IF(D19=1,"Presque terminé !","") | G19: Taux imputation MOD | K19: =K11/K7 -> 324
A20: ='Révision 1 taux'!E23 -> 0 | B20: =K11/K2 -> 6.2645464 | C20: 0.01 | D20: =IF(ISNUMBER(A20),IF(ABS(A20-B20)<=C20,1,0),0) -> 0 | E20: =IF(D20=1,"Ca y est !","")
A21: ='Révision 1 taux'!G24 -> 0 | B21: ='Révision 1 taux'!G21+'Révision 1 taux'!G22+'Révision 1 taux'!G23 -> 41.56 | C21: 0.01 | D21: =IF(ISNUMBER(A21),IF(ABS(A21-B21)<=C21,1,0),0) -> 0 | E21: =IF(D21=1,"Bon calcul","") | H21: =H1 -> Robe noire | I21: =I1 -> Fall Flower | J21: =J1 -> Abeille
G22: Plusieurs centres | K22: TOTAL
G23: Centre 1: H-M | H23: =H3 -> 0.003 | I23: =I3 -> 0.001 | J23: =J3 -> 0 | K23: =(H23*H2)+(I2*I23) -> 1215
G24: Centre 2 : HMOD | H24: 0 | I24: 0.25 | J24: 2.5 | K24: =(I24*I2)+(J2*J24) -> 3875
G26: Coût de fabrication unitaire
G27: MP | H27: =H9 -> 5 | I27: =I9 -> 20 | J27: =J9 -> 100
G28: MOD | H28: =H10 -> 0.3 | I28: =I10 -> 15.3 | J28: =J10 -> 150
G29: FGF C1 | H29: =H23*K32 -> 5.4323457 | I29: =I23*K32 -> 1.8107819 | J29: 0
G30: FGF C2 | H30: 0 | I30: =I24*K33 -> 25.806452 | J30: =J24*K33 -> 258.06452
H31: =H27+H28+H29+H30 -> 10.732346 | I31: =I27+I28+I29+I30 -> 62.917234 | J31: =J27+J28+J29+J30 -> 508.06452
G32: Taux imputation C1 | K32: ='Activité '!E20/Divers!K23 -> 1810.7819
G33: Taux imputation C2 | K33: ='Activité '!G20/Divers!K24 -> 103.22581
