Workbook

Sheet Données
A1: Mois | B1: A2017 | C1: A2018 | D1: A2019 | E1: A2020 | F1: A2021 | G1: A2022 | H1: A2023 | I1: A2024 | J1: A2025
A2: Janvier | B2: 6036 | C2: 5873 | D2: 5895 | E2: 5761 | F2: 5704 | G2: 5534 | H2: 5607 | I2: 5446 | J2: 5503
A3: Février | B3: 6049 | C3: 5991 | D3: 5976 | E3: 5825 | F3: 5831 | G3: 5672 | H3: 5584 | I3: 5591 | J3: 5569
A4: Mars | B4: 5810 | C4: 5807 | D4: 5639 | E4: 5669 | F4: 5585 | G4: 5419 | H4: 5358 | I4: 5377 | J4: 5297
A5: Avril | B5: 6100 | C5: 6076 | D5: 5905 | E5: 5890 | F5: 5677 | G5: 5733 | H5: 5628 | I5: 5505 | J5: 5530
A6: Mai | B6: 6013 | C6: 5905 | D6: 5895 | E6: 5737 | F6: 5697 | G6: 5591 | H6: 5563 | I6: 5525 | J6: 5401
A7: Juin | B7: 6204 | C7: 5976 | D7: 5931 | E7: 5848 | F7: 5836 | G7: 5709 | H7: 5616 | I7: 5502 | J7: 5532
A8: Juillet | B8: 6068 | C8: 5997 | D8: 5861 | E8: 5896 | F8: 5732 | G8: 5622 | H8: 5490 | I8: 5591 | J8: 5495
A9: Août | B9: 6254 | C9: 6182 | D9: 6181 | E9: 6055 | F9: 5948 | G9: 5917 | H9: 5894 | I9: 5781 | J9: 5805
A10: Septembre | B10: 6629 | C10: 6418 | D10: 6355 | E10: 6378 | F10: 6208 | G10: 6131 | H10: 6165 | I10: 6072 | J10: 5999
A11: Octobre | B11: 6137 | C11: 6177 | D11: 6028 | E11: 5998 | F11: 5845 | G11: 5869 | H11: 5677 | I11: 5700 | J11: 5538
A12: Novembre | B12: 6050 | C12: 6037 | D12: 5888 | E12: 5842 | F12: 5724 | G12: 5704 | H12: 5548 | I12: 5465 | J12: 5445
A13: Décembre | B13: 6159 | C13: 5948 | D13: 5954 | E13: 5796 | F13: 5794 | G13: 5627 | H13: 5686 | I13: 5610 | J13: 5535
A14: Total | B14: =SUM(B2:B13) -> 73509 | C14: =SUM(C2:C13) -> 72387 | D14: =SUM(D2:D13) -> 71508 | E14: =SUM(E2:E13) -> 70695 | F14: =SUM(F2:F13) -> 69581 | G14: =SUM(G2:G13) -> 68528 | H14: =SUM(H2:H13) -> 67816 | I14: =SUM(I2:I13) -> 67165 | J14: =SUM(J2:J13) -> 66649
A16: Mois | B16: Demande
A17: 01/01/2017 | B17: 6036
A18: 01/02/2017 | B18: 6049
A19: 01/03/2017 | B19: 5810
A20: 01/04/2017 | B20: 6100
A21: 01/05/2017 | B21: 6013
A22: 01/06/2017 | B22: 6204
A23: 01/07/2017 | B23: 6068
A24: 01/08/2017 | B24: 6254
A25: 01/09/2017 | B25: 6629
A26: 01/10/2017 | B26: 6137
A27: 01/11/2017 | B27: 6050
A28: 01/12/2017 | B28: 6159
... A124: 01/12/2025 | B124: 5535

Sheet Q3 - Prévisions non arrondies
A1: Année | B1: Mois | C1: Demande | D1: Moyenne mobile | E1: Moyenne mobile pondérée | F1: Lissage exponentiel | G1: Lissage exponentiel
D2: K = 6 | E2: K = 4, 10 % - 20 %, 30 %, 40 % | F2: 0.25 | G2: 0.75
A3: 2017 | B3: Janvier | C3: 6036 | F3: =C3 -> 6036 | G3: =C3 -> 6036
B4: Février | C4: 6049 | F4: =F$2*$C3+(1-F$2)*F3 -> 6036 | G4: =G$2*$C3+(1-G$2)*G3 -> 6036
B5: Mars | C5: 5810 | F5: =F$2*$C4+(1-F$2)*F4 -> 6039.25 | G5: =G$2*$C4+(1-G$2)*G4 -> 6045.75
B6: Avril | C6: 6100 | F6: =F$2*$C5+(1-F$2)*F5 -> 5981.9375 | G6: =G$2*$C5+(1-G$2)*G5 -> 5868.9375
B7: Mai | C7: 6013 | E7: =C3*0.1+C4*0.2+C5*0.3+C6*0.4 -> 5996.4 | F7: =F$2*$C6+(1-F$2)*F6 -> 6011.4531 | G7: =G$2*$C6+(1-G$2)*G6 -> 6042.2344
B8: Juin | C8: 6204 | E8: =C4*0.1+C5*0.2+C6*0.3+C7*0.4 -> 6002.1 | F8: =F$2*$C7+(1-F$2)*F7 -> 6011.8398 | G8: =G$2*$C7+(1-G$2)*G7 -> 6020.3086
B9: Juillet | C9: 6068 | D9: =AVERAGE(C3:C8) -> 6035.3333 | E9: =C5*0.1+C6*0.2+C7*0.3+C8*0.4 -> 6086.5 | F9: =F$2*$C8+(1-F$2)*F8 -> 6059.8799 | G9: =G$2*$C8+(1-G$2)*G8 -> 6158.0771
B10: Août | C10: 6254 | D10: =AVERAGE(C4:C9) -> 6040.6667 | E10: =C6*0.1+C7*0.2+C8*0.3+C9*0.4 -> 6101 | F10: =F$2*$C9+(1-F$2)*F9 -> 6061.9099 | G10: =G$2*$C9+(1-G$2)*G9 -> 6090.5193
B11: Septembre | C11: 6629 | D11: =AVERAGE(C5:C10) -> 6074.8333 | E11: =C7*0.1+C8*0.2+C9*0.3+C10*0.4 -> 6164.1 | F11: =F$2*$C10+(1-F$2)*F10 -> 6109.9324 | G11: =G$2*$C10+(1-G$2)*G10 -> 6213.1298
B12: Octobre | C12: 6137 | D12: =AVERAGE(C6:C11) -> 6211.3333 | E12: =C8*0.1+C9*0.2+C10*0.3+C11*0.4 -> 6361.8 | F12: =F$2*$C11+(1-F$2)*F11 -> 6239.6993 | G12: =G$2*$C11+(1-G$2)*G11 -> 6525.0325
B13: Novembre | C13: 6050 | D13: =AVERAGE(C7:C12) -> 6217.5 | E13: =C9*0.1+C10*0.2+C11*0.3+C12*0.4 -> 6301.1 | F13: =F$2*$C12+(1-F$2)*F12 -> 6214.0245 | G13: =G$2*$C12+(1-G$2)*G12 -> 6234.0081
B14: Décembre | C14: 6159 | D14: =AVERAGE(C8:C13) -> 6223.6667 | E14: =C10*0.1+C11*0.2+C12*0.3+C13*0.4 -> 6212.3 | F14: =F$2*$C13+(1-F$2)*F13 -> 6173.0184 | G14: =G$2*$C13+(1-G$2)*G13 -> 6096.002
A15: 2018 | B15: Janvier | C15: 5873 | D15: =AVERAGE(C9:C14) -> 6216.1667 | E15: =C11*0.1+C12*0.2+C13*0.3+C14*0.4 -> 6168.9 | F15: =F$2*$C14+(1-F$2)*F14 -> 6169.5138 | G15: =G$2*$C14+(1-G$2)*G14 -> 6143.2505
A16: 2018 | B16: Février | C16: 5991 | D16: =AVERAGE(C10:C15) -> 6183.6667 | E16: =C12*0.1+C13*0.2+C14*0.3+C15*0.4 -> 6020.6 | F16: =F$2*$C15+(1-F$2)*F15 -> 6095.3853 | G16: =G$2*$C15+(1-G$2)*G15 -> 5940.5626
A17: 2018 | B17: Mars | C17: 5807 | D17: =AVERAGE(C11:C16) -> 6139.8333 | E17: =C13*0.1+C14*0.2+C15*0.3+C16*0.4 -> 5995.1 | F17: =F$2*$C16+(1-F$2)*F16 -> 6069.289 | G17: =G$2*$C16+(1-G$2)*G16 -> 5978.3907
A18: 2018 | B18: Avril | C18: 6076 | D18: =AVERAGE(C12:C17) -> 6002.8333 | E18: =C14*0.1+C15*0.2+C16*0.3+C17*0.4 -> 5910.6 | F18: =F$2*$C17+(1-F$2)*F17 -> 6003.7168 | G18: =G$2*$C17+(1-G$2)*G17 -> 5849.8477
A19: 2018 | B19: Mai | C19: 5905 | D19: =AVERAGE(C13:C18) -> 5992.6667 | E19: =C15*0.1+C16*0.2+C17*0.3+C18*0.4 -> 5958 | F19: =F$2*$C18+(1-F$2)*F18 -> 6021.7876 | G19: =G$2*$C18+(1-G$2)*G18 -> 6019.4619
A20: 2018 | B20: Juin | C20: 5976 | D20: =AVERAGE(C14:C19) -> 5968.5 | E20: =C16*0.1+C17*0.2+C18*0.3+C19*0.4 -> 5945.3 | F20: =F$2*$C19+(1-F$2)*F19 -> 5992.5907 | G20: =G$2*$C19+(1-G$2)*G19 -> 5933.6155
A21: 2018 | B21: Juillet | C21: 5997 | D21: =AVERAGE(C15:C20) -> 5938 | E21: =C17*0.1+C18*0.2+C19*0.3+C20*0.4 -> 5957.8 | F21: =F$2*$C20+(1-F$2)*F20 -> 5988.443 | G21: =G$2*$C20+(1-G$2)*G20 -> 5965.4039
A22: 2018 | B22: Août | C22: 6182 | D22: =AVERAGE(C16:C21) -> 5958.6667 | E22: =C18*0.1+C19*0.2+C20*0.3+C21*0.4 -> 5980.2 | F22: =F$2*$C21+(1-F$2)*F21 -> 5990.5823 | G22: =G$2*$C21+(1-G$2)*G21 -> 5989.101
A23: 2018 | B23: Septembre | C23: 6418 | D23: =AVERAGE(C17:C22) -> 5990.5 | E23: =C19*0.1+C20*0.2+C21*0.3+C22*0.4 -> 6057.6 | F23: =F$2*$C22+(1-F$2)*F22 -> 6038.4367 | G23: =G$2*$C22+(1-G$2)*G22 -> 6133.7752
A24: 2018 | B24: Octobre | C24: 6177 | D24: =AVERAGE(C18:C23) -> 6092.3333 | E24: =C20*0.1+C21*0.2+C22*0.3+C23*0.4 -> 6218.8 | F24: =F$2*$C23+(1-F$2)*F23 -> 6133.3275 | G24: =G$2*$C23+(1-G$2)*G23 -> 6346.9438
A25: 2018 | B25: Novembre | C25: 6037 | D25: =AVERAGE(C19:C24) -> 6109.1667 | E25: =C21*0.1+C22*0.2+C23*0.3+C24*0.4 -> 6232.3 | F25: =F$2*$C24+(1-F$2)*F24 -> 6144.2456 | G25: =G$2*$C24+(1-G$2)*G24 -> 6219.486
A26: 2018 | B26: Décembre | C26: 5948 | D26: =AVERAGE(C20:C25) -> 6131.1667 | E26: =C22*0.1+C23*0.2+C24*0.3+C25*0.4 -> 6169.7 | F26: =F$2*$C25+(1-F$2)*F25 -> 6117.4342 | G26: =G$2*$C25+(1-G$2)*G25 -> 6082.6215
... A110: 2025 | B110: Décembre | C110: 5535 | D110: =AVERAGE(C104:C109) -> 5635.6667 | E110: =C106*0.1+C107*0.2+C108*0.3+C109*0.4 -> 5619.7 | F110: =F$2*$C109+(1-F$2)*F109 -> 5596.1011 | G110: =G$2*$C109+(1-G$2)*G109 -> 5492.8298

Sheet Q3 - Q4 - Prévisions arrondies
A1: Prévisions arrondies 2025
A2: Année | B2: Mois | C2: Demande | D2: Moyenne mobile | E2: Moyenne mobile pondérée | F2: Lissage exponentiel | G2: Lissage exponentiel
D3: K = 6 | E3: K = 4, 10 % - 20 %, 30 %, 40 % | F3: 0.25 | G3: 0.75
A4: 2025 | B4: Janvier | C4: 5503 | D4: =ROUND('Q3 - Prévisions non arrondies'!D99,0) -> 5703 | E4: =ROUND('Q3 - Prévisions non arrondies'!E99,0) -> 5631 | F4: =ROUND('Q3 - Prévisions non arrondies'!F99,0) -> 5643 | G4: =ROUND('Q3 - Prévisions non arrondies'!G99,0) -> 5593
B5: Février | C5: 5569 | D5: =ROUND('Q3 - Prévisions non arrondies'!D100,0) -> 5689 | E5: =ROUND('Q3 - Prévisions non arrondies'!E100,0) -> 5547 | F5: =ROUND('Q3 - Prévisions non arrondies'!F100,0) -> 5608 | G5: =ROUND('Q3 - Prévisions non arrondies'!G100,0) -> 5525
B6: Mars | C6: 5297 | D6: =ROUND('Q3 - Prévisions non arrondies'!D101,0) -> 5653 | E6: =ROUND('Q3 - Prévisions non arrondies'!E101,0) -> 5547 | F6: =ROUND('Q3 - Prévisions non arrondies'!F101,0) -> 5598 | G6: =ROUND('Q3 - Prévisions non arrondies'!G101,0) -> 5558
B7: Avril | C7: 5530 | D7: =ROUND('Q3 - Prévisions non arrondies'!D102,0) -> 5524 | E7: =ROUND('Q3 - Prévisions non arrondies'!E102,0) -> 5451 | F7: =ROUND('Q3 - Prévisions non arrondies'!F102,0) -> 5523 | G7: =ROUND('Q3 - Prévisions non arrondies'!G102,0) -> 5362
B8: Mai | C8: 5401 | D8: =ROUND('Q3 - Prévisions non arrondies'!D103,0) -> 5496 | E8: =ROUND('Q3 - Prévisions non arrondies'!E103,0) -> 5465 | F8: =ROUND('Q3 - Prévisions non arrondies'!F103,0) -> 5525 | G8: =ROUND('Q3 - Prévisions non arrondies'!G103,0) -> 5488
B9: Juin | C9: 5532 | D9: =ROUND('Q3 - Prévisions non arrondies'!D104,0) -> 5485 | E9: =ROUND('Q3 - Prévisions non arrondies'!E104,0) -> 5436 | F9: =ROUND('Q3 - Prévisions non arrondies'!F104,0) -> 5494 | G9: =ROUND('Q3 - Prévisions non arrondies'!G104,0) -> 5423
B10: Juillet | C10: 5495 | D10: =ROUND('Q3 - Prévisions non arrondies'!D105,0) -> 5472 | E10: =ROUND('Q3 - Prévisions non arrondies'!E105,0) -> 5469 | F10: =ROUND('Q3 - Prévisions non arrondies'!F105,0) -> 5503 | G10: =ROUND('Q3 - Prévisions non arrondies'!G105,0) -> 5505
B11: Août | C11: 5805 | D11: =ROUND('Q3 - Prévisions non arrondies'!D106,0) -> 5471 | E11: =ROUND('Q3 - Prévisions non arrondies'!E106,0) -> 5491 | F11: =ROUND('Q3 - Prévisions non arrondies'!F106,0) -> 5501 | G11: =ROUND('Q3 - Prévisions non arrondies'!G106,0) -> 5497
B12: Septembre | C12: 5999 | D12: =ROUND('Q3 - Prévisions non arrondies'!D107,0) -> 5510 | E12: =ROUND('Q3 - Prévisions non arrondies'!E107,0) -> 5617 | F12: =ROUND('Q3 - Prévisions non arrondies'!F107,0) -> 5577 | G12: =ROUND('Q3 - Prévisions non arrondies'!G107,0) -> 5728
B13: Octobre | C13: 5538 | D13: =ROUND('Q3 - Prévisions non arrondies'!D108,0) -> 5627 | E13: =ROUND('Q3 - Prévisions non arrondies'!E108,0) -> 5793 | F13: =ROUND('Q3 - Prévisions non arrondies'!F108,0) -> 5683 | G13: =ROUND('Q3 - Prévisions non arrondies'!G108,0) -> 5931
B14: Novembre | C14: 5445 | D14: =ROUND('Q3 - Prévisions non arrondies'!D109,0) -> 5628 | E14: =ROUND('Q3 - Prévisions non arrondies'!E109,0) -> 5725 | F14: =ROUND('Q3 - Prévisions non arrondies'!F109,0) -> 5646 | G14: =ROUND('Q3 - Prévisions non arrondies'!G109,0) -> 5636
B15: Décembre | C15: 5535 | D15: =ROUND('Q3 - Prévisions non arrondies'!D110,0) -> 5636 | E15: =ROUND('Q3 - Prévisions non arrondies'!E110,0) -> 5620 | F15: =ROUND('Q3 - Prévisions non arrondies'!F110,0) -> 5596 | G15: =ROUND('Q3 - Prévisions non arrondies'!G110,0) -> 5493
A18: Écarts moyens 2025
A19: Année | B19: Mois | C19: Demande | D19: Moyenne mobile | E19: Moyenne mobile pondérée | F19: Lissage exponentiel | G19: Lissage exponentiel
D20: K = 6 | E20: K = 4, 10 % - 20 %, 30 %, 40 % | F20: 0.25 | G20: 0.75
A21: 2025 | B21: Janvier | C21: 5503 | D21: =($C21-D4) -> -200 | E21: =($C21-E4) -> -128 | F21: =($C21-F4) -> -140 | G21: =($C21-G4) -> -90
B22: Février | C22: 5569 | D22: =($C22-D5) -> -120 | E22: =($C22-E5) -> 22 | F22: =($C22-F5) -> -39 | G22: =($C22-G5) -> 44
B23: Mars | C23: 5297 | D23: =($C23-D6) -> -356 | E23: =($C23-E6) -> -250 | F23: =($C23-F6) -> -301 | G23: =($C23-G6) -> -261
B24: Avril | C24: 5530 | D24: =($C24-D7) -> 6 | E24: =($C24-E7) -> 79 | F24: =($C24-F7) -> 7 | G24: =($C24-G7) -> 168
B25: Mai | C25: 5401 | D25: =($C25-D8) -> -95 | E25: =($C25-E8) -> -64 | F25: =($C25-F8) -> -124 | G25: =($C25-G8) -> -87
B26: Juin | C26: 5532 | D26: =($C26-D9) -> 47 | E26: =($C26-E9) -> 96 | F26: =($C26-F9) -> 38 | G26: =($C26-G9) -> 109
B27: Juillet | C27: 5495 | D27: =($C27-D10) -> 23 | E27: =($C27-E10) -> 26 | F27: =($C27-F10) -> -8 | G27: =($C27-G10) -> -10
B28: Août | C28: 5805 | D28: =($C28-D11) -> 334 | E28: =($C28-E11) -> 314 | F28: =($C28-F11) -> 304 | G28: =($C28-G11) -> 308
B29: Septembre | C29: 5999 | D29: =($C29-D12) -> 489 | E29: =($C29-E12) -> 382 | F29: =($C29-F12) -> 422 | G29: =($C29-G12) -> 271
B30: Octobre | C30: 5538 | D30: =($C30-D13) -> -89 | E30: =($C30-E13) -> -255 | F30: =($C30-F13) -> -145 | G30: =($C30-G13) -> -393
B31: Novembre | C31: 5445 | D31: =($C31-D14) -> -183 | E31: =($C31-E14) -> -280 | F31: =($C31-F14) -> -201 | G31: =($C31-G14) -> -191
B32: Décembre | C32: 5535 | D32: =($C32-D15) -> -101 | E32: =($C32-E15) -> -85 | F32: =($C32-F15) -> -61 | G32: =($C32-G15) -> 42
A33: Moyenne (EM) | D33: =AVERAGE(D21:D32) -> -20.416667 | E33: =AVERAGE(E21:E32) -> -11.916667 | F33: =AVERAGE(F21:F32) -> -20.666667 | G33: =AVERAGE(G21:G32) -> -7.5
A36: Écarts quadratiques moyens 2025
A37: Année | B37: Mois | C37: Demande | D37: Moyenne mobile | E37: Moyenne mobile pondérée | F37: Lissage exponentiel | G37: Lissage exponentiel
D38: K = 6 | E38: K = 4, 10 % - 20 %, 30 %, 40 % | F38: 0.25 | G38: 0.75
A39: 2025 | B39: Janvier | C39: 5503 | D39: =D21*D21 -> 40000 | E39: =E21*E21 -> 16384 | F39: =F21*F21 -> 19600 | G39: =G21*G21 -> 8100
B40: Février | C40: 5569 | D40: =D22*D22 -> 14400 | E40: =E22*E22 -> 484 | F40: =F22*F22 -> 1521 | G40: =G22*G22 -> 1936
B41: Mars | C41: 5297 | D41: =D23*D23 -> 126736 | E41: =E23*E23 -> 62500 | F41: =F23*F23 -> 90601 | G41: =G23*G23 -> 68121
B42: Avril | C42: 5530 | D42: =D24*D24 -> 36 | E42: =E24*E24 -> 6241 | F42: =F24*F24 -> 49 | G42: =G24*G24 -> 28224
B43: Mai | C43: 5401 | D43: =D25*D25 -> 9025 | E43: =E25*E25 -> 4096 | F43: =F25*F25 -> 15376 | G43: =G25*G25 -> 7569
B44: Juin | C44: 5532 | D44: =D26*D26 -> 2209 | E44: =E26*E26 -> 9216 | F44: =F26*F26 -> 1444 | G44: =G26*G26 -> 11881
...
